============================= test session starts ==============================
platform linux -- Python 3.12.3, pytest-8.4.1, pluggy-1.6.0 -- /home/edson/repos/BE_AqiFome_RESTfull/.virtual/bin/python3
cachedir: .pytest_cache
rootdir: /home/edson/repos/BE_AqiFome_RESTfull
plugins: anyio-4.9.0, cov-6.2.1, asyncio-1.0.0
asyncio: mode=Mode.STRICT, asyncio_default_fixture_loop_scope=None, asyncio_default_test_loop_scope=function
collecting ... collected 35 items / 1 error

==================================== ERRORS ====================================
_______ ERROR collecting src/tests/core/service/test_favorito_service.py _______
ImportError while importing test module '/home/edson/repos/BE_AqiFome_RESTfull/src/tests/core/service/test_favorito_service.py'.
Hint: make sure your test modules/packages have valid Python names.
Traceback:
/usr/lib/python3.12/importlib/__init__.py:90: in import_module
    return _bootstrap._gcd_import(name[level:], package, level)
           ^^^^^^^^^^^^^^^^^^^^^^^^^^^^^^^^^^^^^^^^^^^^^^^^^^^^
src/tests/core/service/test_favorito_service.py:4: in <module>
    from core.externos.produto import Produto
E   ModuleNotFoundError: No module named 'core.externos'
=========================== short test summary info ============================
ERROR src/tests/core/service/test_favorito_service.py
!!!!!!!!!!!!!!!!!!!! Interrupted: 1 error during collection !!!!!!!!!!!!!!!!!!!!
========================= 1 warning, 1 error in 1.45s ==========================
